<?xml version="1.0" encoding="utf-8"?><testsuites><testsuite errors="0" failures="0" hostname="Maxs-MBP" name="pytest" skipped="0" tests="1" time="5.790" timestamp="2020-06-01T10:53:16.986940"><testcase classname="ray.dashboard.tests.node_stats_test" file="ray/dashboard/tests/node_stats_test.py" line="7" name="test_basic" time="5.690"><system-out>Received data about a client
</system-out><system-err>2020-06-01 10:53:17,089	INFO resource_spec.py:212 -- Starting Ray with 4.93 GiB memory available for workers and up to 0.15 GiB for objects. You can adjust these settings with ray.init(memory=&lt;bytes&gt;, object_store_memory=&lt;bytes&gt;).
2020-06-01 10:53:17,307	WARNING services.py:923 -- Redis failed to start, retrying now.
2020-06-01 10:53:17,448	INFO services.py:1165 -- View the Ray dashboard at #x1B[1m#x1B[32mlocalhost:8265#x1B[39m#x1B[22m
2020-06-01 10:53:18,497	INFO node_stats.py:178 -- NodeStats: subscribed to RAY_REPORTER.*
2020-06-01 10:53:18,497	INFO node_stats.py:182 -- NodeStats: subscribed to RAY_LOG_CHANNEL
2020-06-01 10:53:18,497	INFO node_stats.py:186 -- NodeStats: subscribed to 9
2020-06-01 10:53:18,497	INFO node_stats.py:190 -- NodeStats: subscribed to 6
Exception in thread Thread-1:
Traceback (most recent call last):
  File &quot;/Users/maxfitton/opt/anaconda3/lib/python3.7/threading.py&quot;, line 926, in _bootstrap_inner
    self.run()
  File &quot;/Users/maxfitton/Development/ray/python/ray/dashboard/node_stats.py&quot;, line 207, in run
    for x in p.listen():
  File &quot;/Users/maxfitton/opt/anaconda3/lib/python3.7/site-packages/redis/client.py&quot;, line 3553, in listen
    response = self.handle_message(self.parse_response(block=True))
  File &quot;/Users/maxfitton/opt/anaconda3/lib/python3.7/site-packages/redis/client.py&quot;, line 3453, in parse_response
    response = self._execute(conn, conn.read_response)
  File &quot;/Users/maxfitton/opt/anaconda3/lib/python3.7/site-packages/redis/client.py&quot;, line 3427, in _execute
    return command(*args, **kwargs)
  File &quot;/Users/maxfitton/opt/anaconda3/lib/python3.7/site-packages/redis/connection.py&quot;, line 734, in read_response
    response = self._parser.read_response()
  File &quot;/Users/maxfitton/opt/anaconda3/lib/python3.7/site-packages/redis/connection.py&quot;, line 316, in read_response
    response = self._buffer.readline()
  File &quot;/Users/maxfitton/opt/anaconda3/lib/python3.7/site-packages/redis/connection.py&quot;, line 248, in readline
    self._read_from_socket()
  File &quot;/Users/maxfitton/opt/anaconda3/lib/python3.7/site-packages/redis/connection.py&quot;, line 193, in _read_from_socket
    raise ConnectionError(SERVER_CLOSED_CONNECTION_ERROR)
redis.exceptions.ConnectionError: Connection closed by server.

</system-err></testcase></testsuite></testsuites>